Workbook

Sheet Assumptions
A1: FITNESS APPAREL CO. — KEY ASSUMPTIONS
A3: PRODUCT & PRICING
A4: Average Selling Price (ASP) | B4: 55 | C4: $/unit | D4: Blended across product mix
A5: Cost of Goods Sold (COGS) per Unit | B5: 22 | C5: $/unit | D5: Materials + manufacturing
A6: Gross Margin per Unit | B6: =B4-B5 -> 33 | C6: $/unit | D6: ASP minus COGS
A7: Gross Margin % | B7: =B6/B4 -> 0.6 | C7: % | D7: Margin as % of ASP
A8: Average Units per Order | B8: 2.3 | C8: units | D8: Basket size assumption
A9: Average Order Value (AOV) | B9: =B4*B8 -> 126.5 | C9: $ | D9: ASP × Units per Order
A10: Return Rate | B10: 0.08 | C10: % | D10: Industry avg for apparel
A12: CUSTOMER ACQUISITION
A13: Starting Monthly New Customers (Jan 2026) | B13: 400 | C13: customers | D13: Launch month baseline
A14: Monthly New Customer Growth Rate | B14: 0.06 | C14: %/month | D14: Month-over-month growth
A15: Customer Acquisition Cost (CAC) | B15: 28 | C15: $ | D15: Blended paid + organic
A16: Organic Acquisition Share | B16: 0.25 | C16: % | D16: % of new customers from organic
A17: Paid CAC | B17: 35 | C17: $ | D17: Paid channel CAC
A18: Organic CAC | B18: 5 | C18: $ | D18: SEO, referrals, word-of-mouth
A19: Blended CAC (calculated) | B19: =(1-B16)*B17+B16*B18 -> 27.5 | C19: $ | D19: Weighted average
A21: RETENTION & REPEAT PURCHASES
A22: Month-1 Retention Rate | B22: 0.3 | C22: % | D22: % of new customers who buy again next month
A23: Steady-State Retention Rate | B23: 0.7 | C23: % | D23: Monthly retention of existing repeat customers
A24: Repeat Customer AOV Uplift | B24: 0.1 | C24: % | D24: Repeat customers spend 10% more
A26: OPERATING EXPENSES
A27: Monthly Retail Space Rent | B27: 4500 | C27: $ | D27: Flagship retail location
A28: Retail Utilities & Insurance | B28: 800 | C28: $ | D28: Monthly fixed
A29: Warehouse / Fulfillment | B29: 1200 | C29: $ | D29: 3PL base + variable below
A30: Fulfillment Cost per Order | B30: 3.5 | C30: $/order | D30: Pick, pack, ship
A31: Starting Headcount | B31: 6 | C31: employees | D31: Founders + early team
A32: Average Monthly Salary per Employee | B32: 5500 | C32: $ | D32: Blended avg
A33: Salary Growth Rate (quarterly step) | B33: 0.03 | C33: % | D33: 3% raise each quarter
A34: Headcount Additions per Quarter | B34: 2 | C34: employees | D34: Hiring plan
A35: Marketing Spend as % of Revenue | B35: 0.15 | C35: % | D35: Paid ads, influencers, content
A36: Minimum Monthly Marketing Spend | B36: 5000 | C36: $ | D36: Floor for brand building
A37: Software & Tools | B37: 1500 | C37: $ | D37: Shopify, analytics, CRM
A38: Professional Services (Legal/Acct) | B38: 1000 | C38: $ | D38: Monthly retainer
A39: Miscellaneous / Contingency | B39: 800 | C39: $ | D39: Buffer
A41: INVENTORY MANAGEMENT
A42: Opening Inventory (units) | B42: 2000 | C42: units | D42: Pre-launch stock
A43: Inventory Safety Stock (months of supply) | B43: 1.5 | C43: months | D43: Buffer stock target
A44: Inventory Shrinkage Rate | B44: 0.02 | C44: % | D44: Damage, loss, obsolescence
A45: Reorder Lead Time | B45: 2 | C45: months | D45: Time to replenish
...

Sheet Revenue
A1: FITNESS APPAREL CO. — REVENUE MODEL (12-MONTH FORECAST)
A2: Metric | B2: 46048 | C2: 46079 | D2: 46107 | E2: 46138 | F2: 46168 | G2: 46199 | H2: 46229 | I2: 46260 | J2: 46291 | K2: 46321 | L2: 46352 | M2: 46382 | N2: TOTAL / AVG
A3: CUSTOMER METRICS
A4: New Customers | B4: =Assumptions!B13 -> 400 | C4: =ROUND(B4*(1+Assumptions!B14),0) -> 424 | D4: =ROUND(C4*(1+Assumptions!B14),0) -> 449 | E4: =ROUND(D4*(1+Assumptions!B14),0) -> 476 | F4: =ROUND(E4*(1+Assumptions!B14),0) -> 505 | G4: =ROUND(F4*(1+Assumptions!B14),0) -> 535 | H4: =ROUND(G4*(1+Assumptions!B14),0) -> 567 | I4: =ROUND(H4*(1+Assumptions!B14),0) -> 601 | J4: =ROUND(I4*(1+Assumptions!B14),0) -> 637 | K4: =ROUND(J4*(1+Assumptions!B14),0) -> 675 | L4: =ROUND(K4*(1+Assumptions!B14),0) -> 716 | M4: =ROUND(L4*(1+Assumptions!B14),0) -> 759 | N4: =SUM(B4:M4) -> 6744
A5: Returning Customers | B5: 0 | C5: =ROUND(B4*Assumptions!B22,0) -> 120 | D5: =ROUND(C4*Assumptions!$B$22+C5*Assumptions!$B$23,0) -> 211 | E5: =ROUND(D4*Assumptions!$B$22+D5*Assumptions!$B$23,0) -> 282 | F5: =ROUND(E4*Assumptions!$B$22+E5*Assumptions!$B$23,0) -> 340 | G5: =ROUND(F4*Assumptions!$B$22+F5*Assumptions!$B$23,0) -> 390 | H5: =ROUND(G4*Assumptions!$B$22+G5*Assumptions!$B$23,0) -> 434 | I5: =ROUND(H4*Assumptions!$B$22+H5*Assumptions!$B$23,0) -> 474 | J5: =ROUND(I4*Assumptions!$B$22+I5*Assumptions!$B$23,0) -> 512 | K5: =ROUND(J4*Assumptions!$B$22+J5*Assumptions!$B$23,0) -> 550 | ... M5: =ROUND(L4*Assumptions!$B$22+L5*Assumptions!$B$23,0) -> 626 | N5: =SUM(B5:M5) -> 4527
A6: Total Active Customers | B6: =B4+B5 -> 400 | C6: =C4+C5 -> 544 | D6: =D4+D5 -> 660 | E6: =E4+E5 -> 758 | F6: =F4+F5 -> 845 | G6: =G4+G5 -> 925 | H6: =H4+H5 -> 1001 | I6: =I4+I5 -> 1075 | ... M6: =M4+M5 -> 1385 | N6: =SUM(B6:M6) -> 11271
A7: Retention Rate (%) | B7: =IF(B6=0,0,B5/B6) -> 0 | C7: =IF(C6=0,0,C5/C6) -> 0.22058824 | D7: =IF(D6=0,0,D5/D6) -> 0.31969697 | E7: =IF(E6=0,0,E5/E6) -> 0.37203166 | F7: =IF(F6=0,0,F5/F6) -> 0.40236686 | G7: =IF(G6=0,0,G5/G6) -> 0.42162162 | H7: =IF(H6=0,0,H5/H6) -> 0.43356643 | I7: =IF(I6=0,0,I5/I6) -> 0.44093023 | ... M7: =IF(M6=0,0,M5/M6) -> 0.45198556 | N7: =AVERAGE(B7:M7) -> 0.36735769
A8: Cumulative Unique Customers | B8: =B4 -> 400 | C8: =B8+C4 -> 824 | D8: =C8+D4 -> 1273 | E8: =D8+E4 -> 1749 | F8: =E8+F4 -> 2254 | G8: =F8+G4 -> 2789 | H8: =G8+H4 -> 3356 | I8: =H8+I4 -> 3957 | J8: =I8+J4 -> 4594 | ... M8: =L8+M4 -> 6744 | N8: =M8 -> 6744
A10: ORDER METRICS
A11: Total Orders | B11: =B6 -> 400 | C11: =C6 -> 544 | D11: =D6 -> 660 | E11: =E6 -> 758 | F11: =F6 -> 845 | G11: =G6 -> 925 | H11: =H6 -> 1001 | I11: =I6 -> 1075 | ... M11: =M6 -> 1385 | N11: =SUM(B11:M11) -> 11271
A12: New Customer Orders | B12: =B4 -> 400 | C12: =C4 -> 424 | D12: =D4 -> 449 | E12: =E4 -> 476 | F12: =F4 -> 505 | G12: =G4 -> 535 | H12: =H4 -> 567 | I12: =I4 -> 601 | ... M12: =M4 -> 759 | N12: =SUM(B12:M12) -> 6744
A13: Repeat Customer Orders | B13: =B5 -> 0 | C13: =C5 -> 120 | D13: =D5 -> 211 | E13: =E5 -> 282 | F13: =F5 -> 340 | G13: =G5 -> 390 | H13: =H5 -> 434 | I13: =I5 -> 474 | ... M13: =M5 -> 626 | N13: =SUM(B13:M13) -> 4527
A14: Total Units Sold | B14: =ROUND(B4*Assumptions!$B$8 + B5*Assumptions!$B$8,0) -> 920 | C14: =ROUND(C4*Assumptions!$B$8 + C5*Assumptions!$B$8,0) -> 1251 | D14: =ROUND(D4*Assumptions!$B$8 + D5*Assumptions!$B$8,0) -> 1518 | E14: =ROUND(E4*Assumptions!$B$8 + E5*Assumptions!$B$8,0) -> 1743 | F14: =ROUND(F4*Assumptions!$B$8 + F5*Assumptions!$B$8,0) -> 1944 | G14: =ROUND(G4*Assumptions!$B$8 + G5*Assumptions!$B$8,0) -> 2128 | H14: =ROUND(H4*Assumptions!$B$8 + H5*Assumptions!$B$8,0) -> 2302 | I14: =ROUND(I4*Assumptions!$B$8 + I5*Assumptions!$B$8,0) -> 2473 | ... M14: =ROUND(M4*Assumptions!$B$8 + M5*Assumptions!$B$8,0) -> 3186 | N14: =SUM(B14:M14) -> 25925
A15: Returns (units) | B15: =ROUND(B14*Assumptions!$B$10,0) -> 74 | C15: =ROUND(C14*Assumptions!$B$10,0) -> 100 | D15: =ROUND(D14*Assumptions!$B$10,0) -> 121 | E15: =ROUND(E14*Assumptions!$B$10,0) -> 139 | F15: =ROUND(F14*Assumptions!$B$10,0) -> 156 | G15: =ROUND(G14*Assumptions!$B$10,0) -> 170 | H15: =ROUND(H14*Assumptions!$B$10,0) -> 184 | I15: =ROUND(I14*Assumptions!$B$10,0) -> 198 | ... M15: =ROUND(M14*Assumptions!$B$10,0) -> 255 | N15: =SUM(B15:M15) -> 2073
A16: Net Units Sold | B16: =B14-B15 -> 846 | C16: =C14-C15 -> 1151 | D16: =D14-D15 -> 1397 | E16: =E14-E15 -> 1604 | F16: =F14-F15 -> 1788 | G16: =G14-G15 -> 1958 | H16: =H14-H15 -> 2118 | I16: =I14-I15 -> 2275 | ... M16: =M14-M15 -> 2931 | N16: =SUM(B16:M16) -> 23852
A18: REVENUE
A19: Gross Revenue | B19: =B4*Assumptions!$B$8*Assumptions!$B$4 + B5*Assumptions!$B$8*Assumptions!$B$4*(1+Assumptions!$B$24) -> 50600 | C19: =C4*Assumptions!$B$8*Assumptions!$B$4 + C5*Assumptions!$B$8*Assumptions!$B$4*(1+Assumptions!$B$24) -> 70334 | D19: =D4*Assumptions!$B$8*Assumptions!$B$4 + D5*Assumptions!$B$8*Assumptions!$B$4*(1+Assumptions!$B$24) -> 86159.15 | E19: =E4*Assumptions!$B$8*Assumptions!$B$4 + E5*Assumptions!$B$8*Assumptions!$B$4*(1+Assumptions!$B$24) -> 99454.3 | F19: =F4*Assumptions!$B$8*Assumptions!$B$4 + F5*Assumptions!$B$8*Assumptions!$B$4*(1+Assumptions!$B$24) -> 111193.5 | G19: =G4*Assumptions!$B$8*Assumptions!$B$4 + G5*Assumptions!$B$8*Assumptions!$B$4*(1+Assumptions!$B$24) -> 121946 | H19: =H4*Assumptions!$B$8*Assumptions!$B$4 + H5*Assumptions!$B$8*Assumptions!$B$4*(1+Assumptions!$B$24) -> 132116.6 | I19: =I4*Assumptions!$B$8*Assumptions!$B$4 + I5*Assumptions!$B$8*Assumptions!$B$4*(1+Assumptions!$B$24) -> 141983.6 | ... M19: =M4*Assumptions!$B$8*Assumptions!$B$4 + M5*Assumptions!$B$8*Assumptions!$B$4*(1+Assumptions!$B$24) -> 183121.4 | N19: =SUM(B19:M19) -> 1483048
A20: Less: Returns | B20: =-B15*Assumptions!$B$4 -> -4070 | C20: =-C15*Assumptions!$B$4 -> -5500 | D20: =-D15*Assumptions!$B$4 -> -6655 | E20: =-E15*Assumptions!$B$4 -> -7645 | F20: =-F15*Assumptions!$B$4 -> -8580 | G20: =-G15*Assumptions!$B$4 -> -9350 | H20: =-H15*Assumptions!$B$4 -> -10120 | I20: =-I15*Assumptions!$B$4 -> -10890 | ... M20: =-M15*Assumptions!$B$4 -> -14025 | N20: =SUM(B20:M20) -> -114015
A21: Net Revenue | B21: =B19+B20 -> 46530 | C21: =C19+C20 -> 64834 | D21: =D19+D20 -> 79504.15 | E21: =E19+E20 -> 91809.3 | F21: =F19+F20 -> 102613.5 | G21: =G19+G20 -> 112596 | H21: =H19+H20 -> 121996.6 | I21: =I19+I20 -> 131093.6 | ... M21: =M19+M20 -> 169096.4 | N21: =SUM(B21:M21) -> 1369033
A22: Revenue Growth (MoM) | B22: — | C22: =(C21-B21)/B21 -> 0.39338061 | D22: =(D21-C21)/C21 -> 0.22627248 | E22: =(E21-D21)/D21 -> 0.15477368 | F22: =(F21-E21)/E21 -> 0.11768089 | G22: =(G21-F21)/F21 -> 0.097282521 | H22: =(H21-G21)/G21 -> 0.083489644 | I22: =(I21-H21)/H21 -> 0.074567652 | J22: =(J21-I21)/I21 -> 0.069619722 | ... M22: =(M21-L21)/L21 -> 0.062202015 | N22: =AVERAGE(C22:M22) -> 0.12820848
A24: UNIT ECONOMICS
A25: COGS (Cost of Goods Sold) | B25: =B16*Assumptions!$B$5 -> 18612 | C25: =C16*Assumptions!$B$5 -> 25322 | D25: =D16*Assumptions!$B$5 -> 30734 | E25: =E16*Assumptions!$B$5 -> 35288 | F25: =F16*Assumptions!$B$5 -> 39336 | G25: =G16*Assumptions!$B$5 -> 43076 | H25: =H16*Assumptions!$B$5 -> 46596 | I25: =I16*Assumptions!$B$5 -> 50050 | ... M25: =M16*Assumptions!$B$5 -> 64482 | N25: =SUM(B25:M25) -> 524744
A26: Gross Profit | B26: =B21-B25 -> 27918 | C26: =C21-C25 -> 39512 | D26: =D21-D25 -> 48770.15 | E26: =E21-E25 -> 56521.3 | F26: =F21-F25 -> 63277.5 | G26: =G21-G25 -> 69520 | H26: =H21-H25 -> 75400.6 | I26: =I21-I25 -> 81043.6 | ... M26: =M21-M25 -> 104614.4 | N26: =SUM(B26:M26) -> 844289.05
A27: Gross Margin % | B27: =IF(B21=0,0,B26/B21) -> 0.6 | C27: =IF(C21=0,0,C26/C21) -> 0.60943332 | D27: =IF(D21=0,0,D26/D21) -> 0.61342898 | E27: =IF(E21=0,0,E26/E21) -> 0.61563807 | F27: =IF(F21=0,0,F26/F21) -> 0.61665863 | G27: =IF(G21=0,0,G26/G21) -> 0.61742868 | H27: =IF(H21=0,0,H26/H21) -> 0.61805493 | I27: =IF(I21=0,0,I26/I21) -> 0.61821172 | ... M27: =IF(M21=0,0,M26/M21) -> 0.61866722 | N27: =AVERAGE(B27:M27) -> 0.615267
A28: Revenue per Customer | B28: =IF(B6=0,0,B21/B6) -> 116.325 | C28: =IF(C6=0,0,C21/C6) -> 119.18015 | D28: =IF(D6=0,0,D21/D6) -> 120.46083 | E28: =IF(E6=0,0,E21/E6) -> 121.12045 | F28: =IF(F6=0,0,F21/F6) -> 121.43609 | G28: =IF(G6=0,0,G21/G6) -> 121.72541 | H28: =IF(H6=0,0,H21/H6) -> 121.87473 | I28: =IF(I6=0,0,I21/I6) -> 121.94753 | ... M28: =IF(M6=0,0,M21/M6) -> 122.09126 | N28: =AVERAGE(B28:M28) -> 121.02977
A29: Customer Acquisition Cost | B29: =Assumptions!$B$19 -> 27.5 | C29: =Assumptions!$B$19 -> 27.5 | D29: =Assumptions!$B$19 -> 27.5 | E29: =Assumptions!$B$19 -> 27.5 | F29: =Assumptions!$B$19 -> 27.5 | G29: =Assumptions!$B$19 -> 27.5 | H29: =Assumptions!$B$19 -> 27.5 | I29: =Assumptions!$B$19 -> 27.5 | ... M29: =Assumptions!$B$19 -> 27.5 | N29: =AVERAGE(B29:M29) -> 27.5
A30: LTV:CAC Ratio | B30: =IF(B29=0,0,(B26/B6)/B29) -> 2.538 | C30: =IF(C29=0,0,(C26/C6)/C29) -> 2.6411765 | D30: =IF(D29=0,0,(D26/D6)/D29) -> 2.6870606 | E30: =IF(E29=0,0,(E26/E6)/E29) -> 2.711504 | F30: =IF(F29=0,0,(F26/F6)/F29) -> 2.7230769 | G30: =IF(G29=0,0,(G26/G6)/G29) -> 2.732973 | H30: =IF(H29=0,0,(H26/H6)/H29) -> 2.7391009 | I30: =IF(I29=0,0,(I26/I6)/I29) -> 2.7414326 | ... M30: =IF(M29=0,0,(M26/M6)/M29) -> 2.7466859 | N30: =AVERAGE(B30:M30) -> 2.7081581

Sheet Expenses
A1: FITNESS APPAREL CO. — OPERATING EXPENSES (12-MONTH FORECAST)
A2: Expense Category | B2: 46048 | C2: 46079 | D2: 46107 | E2: 46138 | F2: 46168 | G2: 46199 | H2: 46229 | I2: 46260 | J2: 46291 | K2: 46321 | L2: 46352 | M2: 46382 | N2: TOTAL
A3: INVENTORY & COGS
A4: Cost of Goods Sold | B4: =Revenue!B25 -> 18612 | C4: =Revenue!C25 -> 25322 | D4: =Revenue!D25 -> 30734 | E4: =Revenue!E25 -> 35288 | F4: =Revenue!F25 -> 39336 | G4: =Revenue!G25 -> 43076 | H4: =Revenue!H25 -> 46596 | I4: =Revenue!I25 -> 50050 | ... M4: =Revenue!M25 -> 64482 | N4: =SUM(B4:M4) -> 524744
A5: Inventory Shrinkage | B5: =ROUND(Assumptions!$B$44*Assumptions!$B$42*Assumptions!$B$5,0) -> 880 | C5: =ROUND(Assumptions!$B$44*Assumptions!$B$42*Assumptions!$B$5,0) -> 880 | D5: =ROUND(Assumptions!$B$44*Assumptions!$B$42*Assumptions!$B$5,0) -> 880 | E5: =ROUND(Assumptions!$B$44*Assumptions!$B$42*Assumptions!$B$5,0) -> 880 | F5: =ROUND(Assumptions!$B$44*Assumptions!$B$42*Assumptions!$B$5,0) -> 880 | G5: =ROUND(Assumptions!$B$44*Assumptions!$B$42*Assumptions!$B$5,0) -> 880 | H5: =ROUND(Assumptions!$B$44*Assumptions!$B$42*Assumptions!$B$5,0) -> 880 | I5: =ROUND(Assumptions!$B$44*Assumptions!$B$42*Assumptions!$B$5,0) -> 880 | ... M5: =ROUND(Assumptions!$B$44*Assumptions!$B$42*Assumptions!$B$5,0) -> 880 | N5: =SUM(B5:M5) -> 10560
A6: Fulfillment (Variable) | B6: =Revenue!B11*Assumptions!$B$30 -> 1400 | C6: =Revenue!C11*Assumptions!$B$30 -> 1904 | D6: =Revenue!D11*Assumptions!$B$30 -> 2310 | E6: =Revenue!E11*Assumptions!$B$30 -> 2653 | F6: =Revenue!F11*Assumptions!$B$30 -> 2957.5 | G6: =Revenue!G11*Assumptions!$B$30 -> 3237.5 | H6: =Revenue!H11*Assumptions!$B$30 -> 3503.5 | I6: =Revenue!I11*Assumptions!$B$30 -> 3762.5 | ... M6: =Revenue!M11*Assumptions!$B$30 -> 4847.5 | N6: =SUM(B6:M6) -> 39448.5
A7: Warehouse / Fulfillment (Fixed) | B7: =Assumptions!$B$29 -> 1200 | C7: =Assumptions!$B$29 -> 1200 | D7: =Assumptions!$B$29 -> 1200 | E7: =Assumptions!$B$29 -> 1200 | F7: =Assumptions!$B$29 -> 1200 | G7: =Assumptions!$B$29 -> 1200 | H7: =Assumptions!$B$29 -> 1200 | I7: =Assumptions!$B$29 -> 1200 | ... M7: =Assumptions!$B$29 -> 1200 | N7: =SUM(B7:M7) -> 14400
A8: Total Inventory & COGS | B8: =SUM(B4:B7) -> 22092 | C8: =SUM(C4:C7) -> 29306 | D8: =SUM(D4:D7) -> 35124 | E8: =SUM(E4:E7) -> 40021 | F8: =SUM(F4:F7) -> 44373.5 | G8: =SUM(G4:G7) -> 48393.5 | H8: =SUM(H4:H7) -> 52179.5 | I8: =SUM(I4:I7) -> 55892.5 | ... M8: =SUM(M4:M7) -> 71409.5 | N8: =SUM(B8:M8) -> 589152.5
A10: RETAIL SPACE
A11: Rent | B11: =Assumptions!$B$27 -> 4500 | C11: =Assumptions!$B$27 -> 4500 | D11: =Assumptions!$B$27 -> 4500 | E11: =Assumptions!$B$27 -> 4500 | F11: =Assumptions!$B$27 -> 4500 | G11: =Assumptions!$B$27 -> 4500 | H11: =Assumptions!$B$27 -> 4500 | I11: =Assumptions!$B$27 -> 4500 | ... M11: =Assumptions!$B$27 -> 4500 | N11: =SUM(B11:M11) -> 54000
A12: Utilities & Insurance | B12: =Assumptions!$B$28 -> 800 | C12: =Assumptions!$B$28 -> 800 | D12: =Assumptions!$B$28 -> 800 | E12: =Assumptions!$B$28 -> 800 | F12: =Assumptions!$B$28 -> 800 | G12: =Assumptions!$B$28 -> 800 | H12: =Assumptions!$B$28 -> 800 | I12: =Assumptions!$B$28 -> 800 | ... M12: =Assumptions!$B$28 -> 800 | N12: =SUM(B12:M12) -> 9600
A13: Total Retail Space | B13: =B11+B12 -> 5300 | C13: =C11+C12 -> 5300 | D13: =D11+D12 -> 5300 | E13: =E11+E12 -> 5300 | F13: =F11+F12 -> 5300 | G13: =G11+G12 -> 5300 | H13: =H11+H12 -> 5300 | I13: =I11+I12 -> 5300 | ... M13: =M11+M12 -> 5300 | N13: =SUM(B13:M13) -> 63600
A15: SALARIES & PERSONNEL
A16: Headcount | B16: =Assumptions!$B$31 -> 6 | C16: =B16 -> 6 | D16: =C16 -> 6 | E16: =D16+Assumptions!$B$34 -> 8 | F16: =E16 -> 8 | G16: =F16 -> 8 | H16: =G16+Assumptions!$B$34 -> 10 | I16: =H16 -> 10 | J16: =I16 -> 10 | K16: =J16+Assumptions!$B$34 -> 12 | L16: =K16 -> 12 | M16: =L16 -> 12 | N16: =M16 -> 12
A17: Avg Salary / Employee | B17: =Assumptions!$B$32 -> 5500 | C17: =B17 -> 5500 | D17: =C17 -> 5500 | E17: =D17*(1+Assumptions!$B$33) -> 5665 | F17: =E17 -> 5665 | G17: =F17 -> 5665 | H17: =G17*(1+Assumptions!$B$33) -> 5834.95 | I17: =H17 -> 5834.95 | J17: =I17 -> 5834.95 | K17: =J17*(1+Assumptions!$B$33) -> 6009.9985 | L17: =K17 -> 6009.9985 | M17: =L17 -> 6009.9985 | N17: =AVERAGE(B17:M17) -> 5752.4871
A18: Total Salaries | B18: =B16*B17 -> 33000 | C18: =C16*C17 -> 33000 | D18: =D16*D17 -> 33000 | E18: =E16*E17 -> 45320 | F18: =F16*F17 -> 45320 | G18: =G16*G17 -> 45320 | H18: =H16*H17 -> 58349.5 | I18: =I16*I17 -> 58349.5 | ... M18: =M16*M17 -> 72119.982 | N18: =SUM(B18:M18) -> 626368.45
A20: MARKETING
A21: Marketing Spend (% of Rev) | B21: =MAX(Revenue!B21*Assumptions!$B$35, Assumptions!$B$36) -> 6979.5 | C21: =MAX(Revenue!C21*Assumptions!$B$35, Assumptions!$B$36) -> 9725.1 | D21: =MAX(Revenue!D21*Assumptions!$B$35, Assumptions!$B$36) -> 11925.622 | E21: =MAX(Revenue!E21*Assumptions!$B$35, Assumptions!$B$36) -> 13771.395 | F21: =MAX(Revenue!F21*Assumptions!$B$35, Assumptions!$B$36) -> 15392.025 | G21: =MAX(Revenue!G21*Assumptions!$B$35, Assumptions!$B$36) -> 16889.4 | H21: =MAX(Revenue!H21*Assumptions!$B$35, Assumptions!$B$36) -> 18299.49 | I21: =MAX(Revenue!I21*Assumptions!$B$35, Assumptions!$B$36) -> 19664.04 | ... M21: =MAX(Revenue!M21*Assumptions!$B$35, Assumptions!$B$36) -> 25364.46 | N21: =SUM(B21:M21) -> 205354.96
A22: Customer Acquisition Spend | B22: =Revenue!B4*Assumptions!$B$19 -> 11000 | C22: =Revenue!C4*Assumptions!$B$19 -> 11660 | D22: =Revenue!D4*Assumptions!$B$19 -> 12347.5 | E22: =Revenue!E4*Assumptions!$B$19 -> 13090 | F22: =Revenue!F4*Assumptions!$B$19 -> 13887.5 | G22: =Revenue!G4*Assumptions!$B$19 -> 14712.5 | H22: =Revenue!H4*Assumptions!$B$19 -> 15592.5 | I22: =Revenue!I4*Assumptions!$B$19 -> 16527.5 | ... M22: =Revenue!M4*Assumptions!$B$19 -> 20872.5 | N22: =SUM(B22:M22) -> 185460
A23: Total Marketing | B23: =B21+B22 -> 17979.5 | C23: =C21+C22 -> 21385.1 | D23: =D21+D22 -> 24273.122 | E23: =E21+E22 -> 26861.395 | F23: =F21+F22 -> 29279.525 | G23: =G21+G22 -> 31601.9 | H23: =H21+H22 -> 33891.99 | I23: =I21+I22 -> 36191.54 | ... M23: =M21+M22 -> 46236.96 | N23: =SUM(B23:M23) -> 390814.96
A25: OTHER OPERATING EXPENSES
A26: Software & Tools | B26: =Assumptions!$B$37 -> 1500 | C26: =Assumptions!$B$37 -> 1500 | D26: =Assumptions!$B$37 -> 1500 | E26: =Assumptions!$B$37 -> 1500 | F26: =Assumptions!$B$37 -> 1500 | G26: =Assumptions!$B$37 -> 1500 | H26: =Assumptions!$B$37 -> 1500 | I26: =Assumptions!$B$37 -> 1500 | ... M26: =Assumptions!$B$37 -> 1500 | N26: =SUM(B26:M26) -> 18000
A27: Professional Services | B27: =Assumptions!$B$38 -> 1000 | C27: =Assumptions!$B$38 -> 1000 | D27: =Assumptions!$B$38 -> 1000 | E27: =Assumptions!$B$38 -> 1000 | F27: =Assumptions!$B$38 -> 1000 | G27: =Assumptions!$B$38 -> 1000 | H27: =Assumptions!$B$38 -> 1000 | I27: =Assumptions!$B$38 -> 1000 | ... M27: =Assumptions!$B$38 -> 1000 | N27: =SUM(B27:M27) -> 12000
A28: Depreciation | B28: =Assumptions!$B$49 -> 500 | C28: =Assumptions!$B$49 -> 500 | D28: =Assumptions!$B$49 -> 500 | E28: =Assumptions!$B$49 -> 500 | F28: =Assumptions!$B$49 -> 500 | G28: =Assumptions!$B$49 -> 500 | H28: =Assumptions!$B$49 -> 500 | I28: =Assumptions!$B$49 -> 500 | ... M28: =Assumptions!$B$49 -> 500 | N28: =SUM(B28:M28) -> 6000
A29: Miscellaneous / Contingency | B29: =Assumptions!$B$39 -> 800 | C29: =Assumptions!$B$39 -> 800 | D29: =Assumptions!$B$39 -> 800 | E29: =Assumptions!$B$39 -> 800 | F29: =Assumptions!$B$39 -> 800 | G29: =Assumptions!$B$39 -> 800 | H29: =Assumptions!$B$39 -> 800 | I29: =Assumptions!$B$39 -> 800 | ... M29: =Assumptions!$B$39 -> 800 | N29: =SUM(B29:M29) -> 9600
A30: Total Other OpEx | B30: =SUM(B26:B29) -> 3800 | C30: =SUM(C26:C29) -> 3800 | D30: =SUM(D26:D29) -> 3800 | E30: =SUM(E26:E29) -> 3800 | F30: =SUM(F26:F29) -> 3800 | G30: =SUM(G26:G29) -> 3800 | H30: =SUM(H26:H29) -> 3800 | I30: =SUM(I26:I29) -> 3800 | ... M30: =SUM(M26:M29) -> 3800 | N30: =SUM(B30:M30) -> 45600
A32: TOTAL OPERATING EXPENSES | B32: =B8+B13+B18+B23+B30 -> 82171.5 | C32: =C8+C13+C18+C23+C30 -> 92791.1 | D32: =D8+D13+D18+D23+D30 -> 101497.12 | E32: =E8+E13+E18+E23+E30 -> 121302.39 | F32: =F8+F13+F18+F23+F30 -> 128073.02 | G32: =G8+G13+G18+G23+G30 -> 134415.4 | H32: =H8+H13+H18+H23+H30 -> 153520.99 | I32: =I8+I13+I18+I23+I30 -> 159533.54 | ... M32: =M8+M13+M18+M23+M30 -> 198866.44 | N32: =SUM(B32:M32) -> 1715535.9

Sheet P&L Summary
A1: FITNESS APPAREL CO. — PROFIT & LOSS STATEMENT (JAN – DEC 2026)
B2: 46048 | C2: 46079 | D2: 46107 | E2: 46138 | F2: 46168 | G2: 46199 | H2: 46229 | I2: 46260 | J2: 46291 | K2: 46321 | L2: 46352 | M2: 46382 | N2: FULL YEAR
A3: REVENUE
A4: Gross Revenue | B4: =Revenue!B19 -> 50600 | C4: =Revenue!C19 -> 70334 | D4: =Revenue!D19 -> 86159.15 | E4: =Revenue!E19 -> 99454.3 | F4: =Revenue!F19 -> 111193.5 | G4: =Revenue!G19 -> 121946 | H4: =Revenue!H19 -> 132116.6 | I4: =Revenue!I19 -> 141983.6 | ... M4: =Revenue!M19 -> 183121.4 | N4: =SUM(B4:M4) -> 1483048
A5: Less: Returns | B5: =Revenue!B20 -> -4070 | C5: =Revenue!C20 -> -5500 | D5: =Revenue!D20 -> -6655 | E5: =Revenue!E20 -> -7645 | F5: =Revenue!F20 -> -8580 | G5: =Revenue!G20 -> -9350 | H5: =Revenue!H20 -> -10120 | I5: =Revenue!I20 -> -10890 | ... M5: =Revenue!M20 -> -14025 | N5: =SUM(B5:M5) -> -114015
A6: Net Revenue | B6: =B4+B5 -> 46530 | C6: =C4+C5 -> 64834 | D6: =D4+D5 -> 79504.15 | E6: =E4+E5 -> 91809.3 | F6: =F4+F5 -> 102613.5 | G6: =G4+G5 -> 112596 | H6: =H4+H5 -> 121996.6 | I6: =I4+I5 -> 131093.6 | ... M6: =M4+M5 -> 169096.4 | N6: =SUM(B6:M6) -> 1369033
A8: COST OF GOODS SOLD
A9: COGS | B9: =Revenue!B25 -> 18612 | C9: =Revenue!C25 -> 25322 | D9: =Revenue!D25 -> 30734 | E9: =Revenue!E25 -> 35288 | F9: =Revenue!F25 -> 39336 | G9: =Revenue!G25 -> 43076 | H9: =Revenue!H25 -> 46596 | I9: =Revenue!I25 -> 50050 | ... M9: =Revenue!M25 -> 64482 | N9: =SUM(B9:M9) -> 524744
A10: Fulfillment (Variable) | B10: =Expenses!B6 -> 1400 | C10: =Expenses!C6 -> 1904 | D10: =Expenses!D6 -> 2310 | E10: =Expenses!E6 -> 2653 | F10: =Expenses!F6 -> 2957.5 | G10: =Expenses!G6 -> 3237.5 | H10: =Expenses!H6 -> 3503.5 | I10: =Expenses!I6 -> 3762.5 | ... M10: =Expenses!M6 -> 4847.5 | N10: =SUM(B10:M10) -> 39448.5
A11: Inventory Shrinkage | B11: =Expenses!B5 -> 880 | C11: =Expenses!C5 -> 880 | D11: =Expenses!D5 -> 880 | E11: =Expenses!E5 -> 880 | F11: =Expenses!F5 -> 880 | G11: =Expenses!G5 -> 880 | H11: =Expenses!H5 -> 880 | I11: =Expenses!I5 -> 880 | ... M11: =Expenses!M5 -> 880 | N11: =SUM(B11:M11) -> 10560
A12: Total COGS | B12: =SUM(B9:B11) -> 20892 | C12: =SUM(C9:C11) -> 28106 | D12: =SUM(D9:D11) -> 33924 | E12: =SUM(E9:E11) -> 38821 | F12: =SUM(F9:F11) -> 43173.5 | G12: =SUM(G9:G11) -> 47193.5 | H12: =SUM(H9:H11) -> 50979.5 | I12: =SUM(I9:I11) -> 54692.5 | ... M12: =SUM(M9:M11) -> 70209.5 | N12: =SUM(B12:M12) -> 574752.5
A14: GROSS PROFIT | B14: =B6-B12 -> 25638 | C14: =C6-C12 -> 36728 | D14: =D6-D12 -> 45580.15 | E14: =E6-E12 -> 52988.3 | F14: =F6-F12 -> 59440 | G14: =G6-G12 -> 65402.5 | H14: =H6-H12 -> 71017.1 | I14: =I6-I12 -> 76401.1 | ... M14: =M6-M12 -> 98886.9 | N14: =SUM(B14:M14) -> 794280.55
A15: Gross Margin % | B15: =IF(B6=0,0,B14/B6) -> 0.55099936 | C15: =IF(C6=0,0,C14/C6) -> 0.56649289 | D15: =IF(D6=0,0,D14/D6) -> 0.57330529 | E15: =IF(E6=0,0,E14/E6) -> 0.57715613 | F15: =IF(F6=0,0,F14/F6) -> 0.57926101 | G15: =IF(G6=0,0,G14/G6) -> 0.58085989 | H15: =IF(H6=0,0,H14/H6) -> 0.5821236 | I15: =IF(I6=0,0,I14/I6) -> 0.58279809 | ... N15: =IF(N6=0,0,N14/N6) -> 0.58017631
A17: OPERATING EXPENSES
A18: Retail Space | B18: =Expenses!B13 -> 5300 | C18: =Expenses!C13 -> 5300 | D18: =Expenses!D13 -> 5300 | E18: =Expenses!E13 -> 5300 | F18: =Expenses!F13 -> 5300 | G18: =Expenses!G13 -> 5300 | H18: =Expenses!H13 -> 5300 | I18: =Expenses!I13 -> 5300 | ... M18: =Expenses!M13 -> 5300 | N18: =SUM(B18:M18) -> 63600
A19: Warehouse (Fixed) | B19: =Expenses!B7 -> 1200 | C19: =Expenses!C7 -> 1200 | D19: =Expenses!D7 -> 1200 | E19: =Expenses!E7 -> 1200 | F19: =Expenses!F7 -> 1200 | G19: =Expenses!G7 -> 1200 | H19: =Expenses!H7 -> 1200 | I19: =Expenses!I7 -> 1200 | ... M19: =Expenses!M7 -> 1200 | N19: =SUM(B19:M19) -> 14400
A20: Total Salaries | B20: =Expenses!B18 -> 33000 | C20: =Expenses!C18 -> 33000 | D20: =Expenses!D18 -> 33000 | E20: =Expenses!E18 -> 45320 | F20: =Expenses!F18 -> 45320 | G20: =Expenses!G18 -> 45320 | H20: =Expenses!H18 -> 58349.5 | I20: =Expenses!I18 -> 58349.5 | ... M20: =Expenses!M18 -> 72119.982 | N20: =SUM(B20:M20) -> 626368.45
A21: Total Marketing | B21: =Expenses!B23 -> 17979.5 | C21: =Expenses!C23 -> 21385.1 | D21: =Expenses!D23 -> 24273.122 | E21: =Expenses!E23 -> 26861.395 | F21: =Expenses!F23 -> 29279.525 | G21: =Expenses!G23 -> 31601.9 | H21: =Expenses!H23 -> 33891.99 | I21: =Expenses!I23 -> 36191.54 | ... M21: =Expenses!M23 -> 46236.96 | N21: =SUM(B21:M21) -> 390814.96
A22: Software & Tools | B22: =Expenses!B26 -> 1500 | C22: =Expenses!C26 -> 1500 | D22: =Expenses!D26 -> 1500 | E22: =Expenses!E26 -> 1500 | F22: =Expenses!F26 -> 1500 | G22: =Expenses!G26 -> 1500 | H22: =Expenses!H26 -> 1500 | I22: =Expenses!I26 -> 1500 | ... M22: =Expenses!M26 -> 1500 | N22: =SUM(B22:M22) -> 18000
A23: Professional Services | B23: =Expenses!B27 -> 1000 | C23: =Expenses!C27 -> 1000 | D23: =Expenses!D27 -> 1000 | E23: =Expenses!E27 -> 1000 | F23: =Expenses!F27 -> 1000 | G23: =Expenses!G27 -> 1000 | H23: =Expenses!H27 -> 1000 | I23: =Expenses!I27 -> 1000 | ... M23: =Expenses!M27 -> 1000 | N23: =SUM(B23:M23) -> 12000
A24: Depreciation | B24: =Expenses!B28 -> 500 | C24: =Expenses!C28 -> 500 | D24: =Expenses!D28 -> 500 | E24: =Expenses!E28 -> 500 | F24: =Expenses!F28 -> 500 | G24: =Expenses!G28 -> 500 | H24: =Expenses!H28 -> 500 | I24: =Expenses!I28 -> 500 | ... M24: =Expenses!M28 -> 500 | N24: =SUM(B24:M24) -> 6000
A25: Miscellaneous | B25: =Expenses!B29 -> 800 | C25: =Expenses!C29 -> 800 | D25: =Expenses!D29 -> 800 | E25: =Expenses!E29 -> 800 | F25: =Expenses!F29 -> 800 | G25: =Expenses!G29 -> 800 | H25: =Expenses!H29 -> 800 | I25: =Expenses!I29 -> 800 | ... M25: =Expenses!M29 -> 800 | N25: =SUM(B25:M25) -> 9600
A26: Total Operating Expenses | B26: =SUM(B18:B25) -> 61279.5 | C26: =SUM(C18:C25) -> 64685.1 | D26: =SUM(D18:D25) -> 67573.122 | E26: =SUM(E18:E25) -> 82481.395 | F26: =SUM(F18:F25) -> 84899.525 | G26: =SUM(G18:G25) -> 87221.9 | H26: =SUM(H18:H25) -> 102541.49 | I26: =SUM(I18:I25) -> 104841.04 | ... M26: =SUM(M18:M25) -> 128656.94 | N26: =SUM(B26:M26) -> 1140783.4
A28: EBITDA | B28: =B14-B26+B24 -> -35141.5 | C28: =C14-C26+C24 -> -27457.1 | D28: =D14-D26+D24 -> -21492.973 | E28: =E14-E26+E24 -> -28993.095 | F28: =F14-F26+F24 -> -24959.525 | G28: =G14-G26+G24 -> -21319.4 | H28: =H14-H26+H24 -> -31024.39 | I28: =I14-I26+I24 -> -27939.94 | ... M28: =M14-M26+M24 -> -29270.042 | N28: =SUM(B28:M28) -> -340502.85
A29: EBITDA Margin % | B29: =IF(B6=0,0,B28/B6) -> -0.75524393 | C29: =IF(C6=0,0,C28/C6) -> -0.42349847 | D29: =IF(D6=0,0,D28/D6) -> -0.27033774 | E29: =IF(E6=0,0,E28/E6) -> -0.31579693 | F29: =IF(F6=0,0,F28/F6) -> -0.24323822 | G29: =IF(G6=0,0,G28/G6) -> -0.1893442 | H29: =IF(H6=0,0,H28/H6) -> -0.25430537 | I29: =IF(I6=0,0,I28/I6) -> -0.2131297 | ... N29: =IF(N6=0,0,N28/N6) -> -0.24871777
A31: OPERATING INCOME (EBIT) | B31: =B14-B26 -> -35641.5 | C31: =C14-C26 -> -27957.1 | D31: =D14-D26 -> -21992.973 | E31: =E14-E26 -> -29493.095 | F31: =F14-F26 -> -25459.525 | G31: =G14-G26 -> -21819.4 | H31: =H14-H26 -> -31524.39 | I31: =I14-I26 -> -28439.94 | ... M31: =M14-M26 -> -29770.042 | N31: =SUM(B31:M31) -> -346502.85
A32: Operating Margin % | B32: =IF(B6=0,0,B31/B6) -> -0.76598968 | C32: =IF(C6=0,0,C31/C6) -> -0.43121048 | D32: =IF(D6=0,0,D31/D6) -> -0.27662672 | E32: =IF(E6=0,0,E31/E6) -> -0.321243 | F32: =IF(F6=0,0,F31/F6) -> -0.24811087 | G32: =IF(G6=0,0,G31/G6) -> -0.19378486 | H32: =IF(H6=0,0,H31/H6) -> -0.25840384 | I32: =IF(I6=0,0,I31/I6) -> -0.21694377 | ... N32: =IF(N6=0,0,N31/N6) -> -0.25310043
A34: TAX & NET INCOME
A35: Income Tax (if profitable) | B35: =IF(B31>0, -B31*Assumptions!$B$48, 0) -> 0 | C35: =IF(C31>0, -C31*Assumptions!$B$48, 0) -> 0 | D35: =IF(D31>0, -D31*Assumptions!$B$48, 0) -> 0 | E35: =IF(E31>0, -E31*Assumptions!$B$48, 0) -> 0 | F35: =IF(F31>0, -F31*Assumptions!$B$48, 0) -> 0 | G35: =IF(G31>0, -G31*Assumptions!$B$48, 0) -> 0 | H35: =IF(H31>0, -H31*Assumptions!$B$48, 0) -> 0 | I35: =IF(I31>0, -I31*Assumptions!$B$48, 0) -> 0 | ... M35: =IF(M31>0, -M31*Assumptions!$B$48, 0) -> 0 | N35: =SUM(B35:M35) -> 0
A37: NET INCOME | B37: =B31+B35 -> -35641.5 | C37: =C31+C35 -> -27957.1 | D37: =D31+D35 -> -21992.973 | E37: =E31+E35 -> -29493.095 | F37: =F31+F35 -> -25459.525 | G37: =G31+G35 -> -21819.4 | H37: =H31+H35 -> -31524.39 | I37: =I31+I35 -> -28439.94 | ... M37: =M31+M35 -> -29770.042 | N37: =SUM(B37:M37) -> -346502.85
A38: Net Margin % | B38: =IF(B6=0,0,B37/B6) -> -0.76598968 | C38: =IF(C6=0,0,C37/C6) -> -0.43121048 | D38: =IF(D6=0,0,D37/D6) -> -0.27662672 | E38: =IF(E6=0,0,E37/E6) -> -0.321243 | F38: =IF(F6=0,0,F37/F6) -> -0.24811087 | G38: =IF(G6=0,0,G37/G6) -> -0.19378486 | H38: =IF(H6=0,0,H37/H6) -> -0.25840384 | I38: =IF(I6=0,0,I37/I6) -> -0.21694377 | ... N38: =IF(N6=0,0,N37/N6) -> -0.25310043
A39: Cumulative Net Income | B39: =B37 -> -35641.5 | C39: =B39+C37 -> -63598.6 | D39: =C39+D37 -> -85591.573 | E39: =D39+E37 -> -115084.67 | F39: =E39+F37 -> -140544.19 | G39: =F39+G37 -> -162363.59 | H39: =G39+H37 -> -193887.98 | I39: =H39+I37 -> -222327.92 | J39: =I39+J37 -> -247713.17 | ... M39: =L39+M37 -> -346502.85 | N39: =M39 -> -346502.85
A41: KEY PERFORMANCE INDICATORS
A42: KPI | B42: 46048 | C42: 46079 | D42: 46107 | E42: 46138 | F42: 46168 | G42: 46199 | H42: 46229 | I42: 46260 | J42: 46291 | K42: 46321 | L42: 46352 | M42: 46382 | N42: FULL YEAR
A43: Revenue Growth (MoM) | B43: — | C43: =Revenue!C22 -> 0.39338061 | D43: =Revenue!D22 -> 0.22627248 | E43: =Revenue!E22 -> 0.15477368 | F43: =Revenue!F22 -> 0.11768089 | G43: =Revenue!G22 -> 0.097282521 | H43: =Revenue!H22 -> 0.083489644 | I43: =Revenue!I22 -> 0.074567652 | J43: =Revenue!J22 -> 0.069619722 | ... M43: =Revenue!M22 -> 0.062202015 | N43: =AVERAGE(C43:M43) -> 0.12820848
A44: Customer Retention Rate | B44: =Revenue!B7 -> 0 | C44: =Revenue!C7 -> 0.22058824 | D44: =Revenue!D7 -> 0.31969697 | E44: =Revenue!E7 -> 0.37203166 | F44: =Revenue!F7 -> 0.40236686 | G44: =Revenue!G7 -> 0.42162162 | H44: =Revenue!H7 -> 0.43356643 | I44: =Revenue!I7 -> 0.44093023 | ... M44: =Revenue!M7 -> 0.45198556 | N44: =AVERAGE(B44:M44) -> 0.36735769
A45: Repeat Customer Mix % | B45: =IF(Revenue!B6=0,0,Revenue!B5/Revenue!B6) -> 0 | C45: =IF(Revenue!C6=0,0,Revenue!C5/Revenue!C6) -> 0.22058824 | D45: =IF(Revenue!D6=0,0,Revenue!D5/Revenue!D6) -> 0.31969697 | E45: =IF(Revenue!E6=0,0,Revenue!E5/Revenue!E6) -> 0.37203166 | F45: =IF(Revenue!F6=0,0,Revenue!F5/Revenue!F6) -> 0.40236686 | G45: =IF(Revenue!G6=0,0,Revenue!G5/Revenue!G6) -> 0.42162162 | H45: =IF(Revenue!H6=0,0,Revenue!H5/Revenue!H6) -> 0.43356643 | I45: =IF(Revenue!I6=0,0,Revenue!I5/Revenue!I6) -> 0.44093023 | ... M45: =IF(Revenue!M6=0,0,Revenue!M5/Revenue!M6) -> 0.45198556 | N45: =AVERAGE(B45:M45) -> 0.36735769
A46: Gross Margin % | B46: =B15 -> 0.55099936 | C46: =C15 -> 0.56649289 | D46: =D15 -> 0.57330529 | E46: =E15 -> 0.57715613 | F46: =F15 -> 0.57926101 | G46: =G15 -> 0.58085989 | H46: =H15 -> 0.5821236 | I46: =I15 -> 0.58279809 | ... N46: =N15 -> 0.58017631
A47: EBITDA Margin % | B47: =B29 -> -0.75524393 | C47: =C29 -> -0.42349847 | D47: =D29 -> -0.27033774 | E47: =E29 -> -0.31579693 | F47: =F29 -> -0.24323822 | G47: =G29 -> -0.1893442 | H47: =H29 -> -0.25430537 | I47: =I29 -> -0.2131297 | ... N47: =N29 -> -0.24871777
A48: Net Margin % | B48: =B38 -> -0.76598968 | C48: =C38 -> -0.43121048 | D48: =D38 -> -0.27662672 | E48: =E38 -> -0.321243 | F48: =F38 -> -0.24811087 | G48: =G38 -> -0.19378486 | H48: =H38 -> -0.25840384 | I48: =I38 -> -0.21694377 | ... N48: =N38 -> -0.25310043
...
