Workbook
Name FulfillmentOptions: #REF!
Name OrderQty: #REF!

Sheet global_inventory_export11182025
A1: SKU ID | B1: Product Name | C1: Category | D1: Size | E1: Color | F1: Warehouse Code | G1: Location ZIP | H1: Qty On Hand | I1: Qty Allocated | J1: Qty Available | K1: Reorder Point | L1: Bin Location | M1: Lot Number | N1: Vendor ID | O1: Status | P1: Picker ID | Q1: Zone
A2: ZCFET-SS-L-B | B2: ZavaCore Field Elite Tee | C2: Apparel | D2: Large | E2: Black | F2: SAN | G2: 94102 | H2: 6 | I2: 1 | J2: =MAX(Inventory[[#This Row],[Qty On Hand]]-Inventory[[#This Row],[Qty Allocated]],0) -> 5 | K2: 621 | L2: A20-7 | M2: LOT57222 | N2: VEND-345 | O2: Active | P2: P354 | Q2: C
A3: ZCFET-SS-L-B | B3: ZavaCore Field Elite Tee | C3: Apparel | D3: Large | E3: Black | F3: WOO | G3: 98072 | H3: 2167 | I3: 95 | J3: =MAX(Inventory[[#This Row],[Qty On Hand]]-Inventory[[#This Row],[Qty Allocated]],0) -> 2072 | K3: 549 | L3: A44-9 | M3: LOT39815 | N3: VEND-525 | O3: Active | P3: P718 | Q3: B
A4: ZCFET-SS-L-B | B4: ZavaCore Field Elite Tee | C4: Apparel | D4: Large | E4: Black | F4: DAL | G4: 75201 | H4: 134 | I4: 1 | J4: =MAX(Inventory[[#This Row],[Qty On Hand]]-Inventory[[#This Row],[Qty Allocated]],0) -> 133 | K4: 285 | L4: C11-17 | M4: LOT75131 | N4: VEND-406 | O4: Active | P4: P889 | Q4: D
A5: ZCFET-SS-L-B | B5: ZavaCore Field Elite Tee | C5: Apparel | D5: Large | E5: Black | F5: DAL | G5: 75201 | H5: 168 | I5: 94 | J5: =MAX(Inventory[[#This Row],[Qty On Hand]]-Inventory[[#This Row],[Qty Allocated]],0) -> 74 | K5: 276 | L5: D12-19 | M5: LOT94375 | N5: VEND-643 | O5: Active | P5: P987 | Q5: B
A6: ZCFET-SS-L-B | B6: ZavaCore Field Elite Tee | C6: Apparel | D6: Large | E6: Black | F6: DAL | G6: 75201 | H6: 143 | I6: 17 | J6: =MAX(Inventory[[#This Row],[Qty On Hand]]-Inventory[[#This Row],[Qty Allocated]],0) -> 126 | K6: 177 | L6: C56-12 | M6: LOT29415 | N6: VEND-495 | O6: Low Stock | P6: P629 | Q6: B
A7: ZCFET-SS-L-B | B7: ZavaCore Field Elite Tee | C7: Apparel | D7: Large | E7: Black | F7: DAL | G7: 75201 | H7: 92 | I7: 85 | J7: =MAX(Inventory[[#This Row],[Qty On Hand]]-Inventory[[#This Row],[Qty Allocated]],0) -> 7 | K7: 280 | L7: B40-17 | M7: LOT60261 | N7: VEND-538 | O7: Low Stock | P7: P218 | Q7: C
A8: ZCFET-SS-L-B | B8: ZavaCore Field Elite Tee | C8: Apparel | D8: Large | E8: Black | F8: DAL | G8: 75201 | H8: 181 | I8: 64 | J8: =MAX(Inventory[[#This Row],[Qty On Hand]]-Inventory[[#This Row],[Qty Allocated]],0) -> 117 | K8: 207 | L8: A25-15 | M8: LOT85863 | N8: VEND-200 | O8: Low Stock | P8: P797 | Q8: D
A9: ZCFET-SS-L-B | B9: ZavaCore Field Elite Tee | C9: Apparel | D9: Large | E9: Black | F9: DAL | G9: 75201 | H9: 169 | I9: 89 | J9: =MAX(Inventory[[#This Row],[Qty On Hand]]-Inventory[[#This Row],[Qty Allocated]],0) -> 80 | K9: 165 | L9: C46-9 | M9: LOT18797 | N9: VEND-971 | O9: Active | P9: P569 | Q9: B
A10: ZCFET-SS-L-B | B10: ZavaCore Field Elite Tee | C10: Apparel | D10: Large | E10: Black | F10: STL | G10: 63101 | H10: 129 | I10: 67 | J10: =MAX(Inventory[[#This Row],[Qty On Hand]]-Inventory[[#This Row],[Qty Allocated]],0) -> 62 | K10: 307 | L10: B13-19 | M10: LOT25363 | N10: VEND-493 | O10: Active | P10: P469 | Q10: C
A11: ZCFET-SS-L-B | B11: ZavaCore Field Elite Tee | C11: Apparel | D11: Large | E11: Black | F11: STL | G11: 63101 | H11: 84 | I11: 26 | J11: =MAX(Inventory[[#This Row],[Qty On Hand]]-Inventory[[#This Row],[Qty Allocated]],0) -> 58 | K11: 195 | L11: A12-3 | M11: LOT23547 | N11: VEND-672 | O11: Active | P11: P700 | Q11: D
A12: ZCFET-SS-L-B | B12: ZavaCore Field Elite Tee | C12: Apparel | D12: Large | E12: Black | F12: STL | G12: 63101 | H12: 180 | I12: 76 | J12: =MAX(Inventory[[#This Row],[Qty On Hand]]-Inventory[[#This Row],[Qty Allocated]],0) -> 104 | K12: 257 | L12: C36-6 | M12: LOT86300 | N12: VEND-269 | O12: Active | P12: P896 | Q12: C
A13: ZCFET-SS-L-B | B13: ZavaCore Field Elite Tee | C13: Apparel | D13: Large | E13: Black | F13: STL | G13: 63101 | H13: 103 | I13: 63 | J13: =MAX(Inventory[[#This Row],[Qty On Hand]]-Inventory[[#This Row],[Qty Allocated]],0) -> 40 | K13: 134 | L13: B29-19 | M13: LOT88629 | N13: VEND-485 | O13: Low Stock | P13: P917 | Q13: C
... A789: ZCSC-SS-9-O | B789: ZavaCore Smart Cleats | C789: Footwear | D789: US 9 | E789: Orange | F789: CLT | G789: 28202 | H789: 625 | I789: 39 | J789: =MAX(Inventory[[#This Row],[Qty On Hand]]-Inventory[[#This Row],[Qty Allocated]],0) -> 586 | K789: 100 | L789: C44-14 | M789: LOT81498 | N789: VEND-571 | O789: Active | P789: P698 | Q789: C

Sheet demo_prompts
A1: Scenario prompts (copy/paste into your assistant)
A2: Do we have enough inventory across warehouses to get an order of 17K shirts to SF asap?
A3: If we prioritize speed, propose allocations by warehouse to fulfill 17K tees (same product & color) to SF.
A4: Suggest fastest mix from STL/DAL/WOO, minimize split shipments, ensure shipment meets need-by date.
A5: Return a short stock table and a confirmation message: 'Inventory Sufficient'.
A6: If SAN is short, automatically re-route from STL/DAL/WOO with expedited shipping notes.
A7: Give at least two options that reach 17K of the same shirt+color; none from a single site only.
A8: When product is 'ZavaCore Field Elite Tee' in Black, target ~62% STL, ~21% DAL, ~17% WOO.
A9: Include the message: Will meet deadline. No stress needed, just expedite shipping.
A11: Order Qty | B11: 17000
A12: Product | B12: ZavaCore Field Elite Tee
A13: Color | B13: Black
A14: Destination City | B14: San Francisco
A15: Destination ZIP | B15: 94102 | D15: Helper (calc)
A16: Need-by Date | B16: 45981 | C16: Adjusted Available (post-transfer)
A17: STL Available | B17: =SUMIFS(global_inventory_export11182025!$J$2:$J$1235,global_inventory_export11182025!$B$2:$B$1235,"ZavaCore Field Elite Tee",global_inventory_export11182025!$E$2:$E$1235,"Black",global_inventory_export11182025!$F$2:$F$1235,"STL") -> 11838 | C17: =_xlfn.LET(_xlpm.STL,B17,_xlpm.DAL,B18,_xlpm.WOO,B19,_xlpm.SAN,B20,_xlpm.X,MAX(0,_xlpm.WOO-7999),_xlpm.SANADD,MIN(_xlpm.X,MAX(0,1000-_xlpm.SAN)),_xlpm.STL) -> 11838 | D17: =$E$23 -> 9920
A18: DAL Available | B18: =SUMIFS(global_inventory_export11182025!$J$2:$J$1235,global_inventory_export11182025!$B$2:$B$1235,"ZavaCore Field Elite Tee",global_inventory_export11182025!$E$2:$E$1235,"Black",global_inventory_export11182025!$F$2:$F$1235,"DAL") -> 5011 | C18: =_xlfn.LET(_xlpm.STL,B17,_xlpm.DAL,B18,_xlpm.WOO,B19,_xlpm.SAN,B20,_xlpm.X,MAX(0,_xlpm.WOO-7999),_xlpm.SANADD,MIN(_xlpm.X,MAX(0,1000-_xlpm.SAN)),_xlpm.DAL+(_xlpm.X-_xlpm.SANADD)) -> 7254 | D18: =$E$26 -> 1277
A19: WOO Available | B19: =SUMIFS(global_inventory_export11182025!$J$2:$J$1235,global_inventory_export11182025!$B$2:$B$1235,"ZavaCore Field Elite Tee",global_inventory_export11182025!$E$2:$E$1235,"Black",global_inventory_export11182025!$F$2:$F$1235,"WOO") -> 11224 | C19: =_xlfn.LET(_xlpm.STL,B17,_xlpm.DAL,B18,_xlpm.WOO,B19,_xlpm.SAN,B20,_xlpm.X,MAX(0,_xlpm.WOO-7999),_xlpm.SANADD,MIN(_xlpm.X,MAX(0,1000-_xlpm.SAN)),_xlpm.WOO-_xlpm.X) -> 7999 | D19: =$E$28 -> 4803
A20: SAN Available | B20: =SUMIFS(global_inventory_export11182025!$J$2:$J$1235,global_inventory_export11182025!$B$2:$B$1235,"ZavaCore Field Elite Tee",global_inventory_export11182025!$E$2:$E$1235,"Black",global_inventory_export11182025!$F$2:$F$1235,"SAN") -> 18 | C20: =_xlfn.LET(_xlpm.STL,B17,_xlpm.DAL,B18,_xlpm.WOO,B19,_xlpm.SAN,B20,_xlpm.X,MAX(0,_xlpm.WOO-7999),_xlpm.SANADD,MIN(_xlpm.X,MAX(0,1000-_xlpm.SAN)),_xlpm.SAN+_xlpm.SANADD) -> 1000 | D20: =$E$20 -> 1000 | E20: =MIN($C$20,1000,$B$11) -> 1000
E21: =$B$11-$E$20 -> 16000
A22: Total Suggested | B22: =SUM($D$17:$D$20) -> 17000 | E22: =ROUND(0.62*$E$21,0) -> 9920
A23: Status | B23: =IF(SUM($C$17:$C$20)>=$B$11,"Inventory Sufficient","Insufficient") -> Inventory Sufficient | E23: =MIN($C$17,$E$22) -> 9920
A24: Message | B24: Will meet deadline. No stress needed, just expedite shipping. | E24: =$E$21-$E$23 -> 6080
E25: =ROUND(0.21*$E$24,0) -> 1277
E26: =MIN($C$18,$E$25) -> 1277
E27: =$B$11-$E$20-$E$23-$E$26 -> 4803
E28: =MIN($C$19,$E$27) -> 4803

Sheet Inventory Dashboard
A1: WAREHOUSE INVENTORY SUMMARY
A2: Warehouse | B2: Total SKU Lines | C2: Qty On Hand | D2: Qty Allocated | E2: Qty Available | F2: Avg Reorder Point | G2: Lines Below Reorder | H2: % Lines At Risk
A3: CLT | B3: =COUNTIF(global_inventory_export11182025!F:F,"CLT") -> 218 | C3: =SUMIF(global_inventory_export11182025!F:F,"CLT",global_inventory_export11182025!H:H) -> 80730 | D3: =SUMIF(global_inventory_export11182025!F:F,"CLT",global_inventory_export11182025!I:I) -> 10289 | E3: =SUMIF(global_inventory_export11182025!F:F,"CLT",global_inventory_export11182025!J:J) -> 70485 | F3: =AVERAGEIF(global_inventory_export11182025!F:F,"CLT",global_inventory_export11182025!K:K) -> 240.68349 | G3: {=SUMPRODUCT((global_inventory_export11182025!F$2:F$789="CLT")*(global_inventory_export11182025!J$2:J$789<global_inventory_export11182025!K$2:K$789))} -> 121 | H3: =IF(B3=0,0,G3/B3) -> 0.55504587
A4: DAL | B4: =COUNTIF(global_inventory_export11182025!F:F,"DAL") -> 242 | C4: =SUMIF(global_inventory_export11182025!F:F,"DAL",global_inventory_export11182025!H:H) -> 88486 | D4: =SUMIF(global_inventory_export11182025!F:F,"DAL",global_inventory_export11182025!I:I) -> 11423 | E4: =SUMIF(global_inventory_export11182025!F:F,"DAL",global_inventory_export11182025!J:J) -> 77110 | F4: =AVERAGEIF(global_inventory_export11182025!F:F,"DAL",global_inventory_export11182025!K:K) -> 250.66942 | G4: {=SUMPRODUCT((global_inventory_export11182025!F$2:F$789="DAL")*(global_inventory_export11182025!J$2:J$789<global_inventory_export11182025!K$2:K$789))} -> 135 | H4: =IF(B4=0,0,G4/B4) -> 0.55785124
A5: SAN | B5: =COUNTIF(global_inventory_export11182025!F:F,"SAN") -> 40 | C5: =SUMIF(global_inventory_export11182025!F:F,"SAN",global_inventory_export11182025!H:H) -> 207 | D5: =SUMIF(global_inventory_export11182025!F:F,"SAN",global_inventory_export11182025!I:I) -> 78 | E5: =SUMIF(global_inventory_export11182025!F:F,"SAN",global_inventory_export11182025!J:J) -> 129 | F5: =AVERAGEIF(global_inventory_export11182025!F:F,"SAN",global_inventory_export11182025!K:K) -> 447.15 | G5: {=SUMPRODUCT((global_inventory_export11182025!F$2:F$789="SAN")*(global_inventory_export11182025!J$2:J$789<global_inventory_export11182025!K$2:K$789))} -> 40 | H5: =IF(B5=0,0,G5/B5) -> 1
A6: STL | B6: =COUNTIF(global_inventory_export11182025!F:F,"STL") -> 240 | C6: =SUMIF(global_inventory_export11182025!F:F,"STL",global_inventory_export11182025!H:H) -> 97710 | D6: =SUMIF(global_inventory_export11182025!F:F,"STL",global_inventory_export11182025!I:I) -> 11250 | E6: =SUMIF(global_inventory_export11182025!F:F,"STL",global_inventory_export11182025!J:J) -> 86484 | F6: =AVERAGEIF(global_inventory_export11182025!F:F,"STL",global_inventory_export11182025!K:K) -> 248.93333 | G6: {=SUMPRODUCT((global_inventory_export11182025!F$2:F$789="STL")*(global_inventory_export11182025!J$2:J$789<global_inventory_export11182025!K$2:K$789))} -> 132 | H6: =IF(B6=0,0,G6/B6) -> 0.55
A7: WOO | B7: =COUNTIF(global_inventory_export11182025!F:F,"WOO") -> 48 | C7: =SUMIF(global_inventory_export11182025!F:F,"WOO",global_inventory_export11182025!H:H) -> 47377 | D7: =SUMIF(global_inventory_export11182025!F:F,"WOO",global_inventory_export11182025!I:I) -> 1416 | E7: =SUMIF(global_inventory_export11182025!F:F,"WOO",global_inventory_export11182025!J:J) -> 45961 | F7: =AVERAGEIF(global_inventory_export11182025!F:F,"WOO",global_inventory_export11182025!K:K) -> 339.02083 | G7: {=SUMPRODUCT((global_inventory_export11182025!F$2:F$789="WOO")*(global_inventory_export11182025!J$2:J$789<global_inventory_export11182025!K$2:K$789))} -> 27 | H7: =IF(B7=0,0,G7/B7) -> 0.5625
A8: TOTAL | B8: =SUM(B3:B7) -> 788 | C8: =SUM(C3:C7) -> 314510 | D8: =SUM(D3:D7) -> 34456 | E8: =SUM(E3:E7) -> 280169 | F8: =AVERAGE(F3:F7) -> 305.29141 | G8: =SUM(G3:G7) -> 455 | H8: =IF(B8=0,0,G8/B8) -> 0.57741117
A10: AVAILABLE INVENTORY BY PRODUCT × WAREHOUSE
A11: Product | B11: CLT | C11: DAL | D11: SAN | E11: STL | F11: WOO | G11: TOTAL | H11: Avg per WH
A12: ZavaCore Field Elite Tee | B12: =SUMIFS(global_inventory_export11182025!J:J,global_inventory_export11182025!B:B,"ZavaCore Field Elite Tee",global_inventory_export11182025!F:F,"CLT") -> 4496 | C12: =SUMIFS(global_inventory_export11182025!J:J,global_inventory_export11182025!B:B,"ZavaCore Field Elite Tee",global_inventory_export11182025!F:F,"DAL") -> 8114 | D12: =SUMIFS(global_inventory_export11182025!J:J,global_inventory_export11182025!B:B,"ZavaCore Field Elite Tee",global_inventory_export11182025!F:F,"SAN") -> 47 | E12: =SUMIFS(global_inventory_export11182025!J:J,global_inventory_export11182025!B:B,"ZavaCore Field Elite Tee",global_inventory_export11182025!F:F,"STL") -> 14224 | F12: =SUMIFS(global_inventory_export11182025!J:J,global_inventory_export11182025!B:B,"ZavaCore Field Elite Tee",global_inventory_export11182025!F:F,"WOO") -> 11224 | G12: =SUM(B12:F12) -> 38105 | H12: =AVERAGE(B12:F12) -> 7621
A13: ZavaCore Field Premium Tee | B13: =SUMIFS(global_inventory_export11182025!J:J,global_inventory_export11182025!B:B,"ZavaCore Field Premium Tee",global_inventory_export11182025!F:F,"CLT") -> 4061 | C13: =SUMIFS(global_inventory_export11182025!J:J,global_inventory_export11182025!B:B,"ZavaCore Field Premium Tee",global_inventory_export11182025!F:F,"DAL") -> 6050 | D13: =SUMIFS(global_inventory_export11182025!J:J,global_inventory_export11182025!B:B,"ZavaCore Field Premium Tee",global_inventory_export11182025!F:F,"SAN") -> 35 | E13: =SUMIFS(global_inventory_export11182025!J:J,global_inventory_export11182025!B:B,"ZavaCore Field Premium Tee",global_inventory_export11182025!F:F,"STL") -> 6501 | F13: =SUMIFS(global_inventory_export11182025!J:J,global_inventory_export11182025!B:B,"ZavaCore Field Premium Tee",global_inventory_export11182025!F:F,"WOO") -> 15004 | G13: =SUM(B13:F13) -> 31651 | H13: =AVERAGE(B13:F13) -> 6330.2
A14: ZavaCore Systems Athletic Jersey | B14: =SUMIFS(global_inventory_export11182025!J:J,global_inventory_export11182025!B:B,"ZavaCore Systems Athletic Jersey",global_inventory_export11182025!F:F,"CLT") -> 28603 | C14: =SUMIFS(global_inventory_export11182025!J:J,global_inventory_export11182025!B:B,"ZavaCore Systems Athletic Jersey",global_inventory_export11182025!F:F,"DAL") -> 28731 | D14: =SUMIFS(global_inventory_export11182025!J:J,global_inventory_export11182025!B:B,"ZavaCore Systems Athletic Jersey",global_inventory_export11182025!F:F,"SAN") -> 24 | E14: =SUMIFS(global_inventory_export11182025!J:J,global_inventory_export11182025!B:B,"ZavaCore Systems Athletic Jersey",global_inventory_export11182025!F:F,"STL") -> 32936 | F14: =SUMIFS(global_inventory_export11182025!J:J,global_inventory_export11182025!B:B,"ZavaCore Systems Athletic Jersey",global_inventory_export11182025!F:F,"WOO") -> 17972 | G14: =SUM(B14:F14) -> 108266 | H14: =AVERAGE(B14:F14) -> 21653.2
A15: ZavaCore Smart Cleats | B15: =SUMIFS(global_inventory_export11182025!J:J,global_inventory_export11182025!B:B,"ZavaCore Smart Cleats",global_inventory_export11182025!F:F,"CLT") -> 33325 | C15: =SUMIFS(global_inventory_export11182025!J:J,global_inventory_export11182025!B:B,"ZavaCore Smart Cleats",global_inventory_export11182025!F:F,"DAL") -> 34215 | D15: =SUMIFS(global_inventory_export11182025!J:J,global_inventory_export11182025!B:B,"ZavaCore Smart Cleats",global_inventory_export11182025!F:F,"SAN") -> 23 | E15: =SUMIFS(global_inventory_export11182025!J:J,global_inventory_export11182025!B:B,"ZavaCore Smart Cleats",global_inventory_export11182025!F:F,"STL") -> 32823 | F15: =SUMIFS(global_inventory_export11182025!J:J,global_inventory_export11182025!B:B,"ZavaCore Smart Cleats",global_inventory_export11182025!F:F,"WOO") -> 1761 | G15: =SUM(B15:F15) -> 102147 | H15: =AVERAGE(B15:F15) -> 20429.4
A16: TOTAL | B16: =SUM(B12:B15) -> 70485 | C16: =SUM(C12:C15) -> 77110 | D16: =SUM(D12:D15) -> 129 | E16: =SUM(E12:E15) -> 86484 | F16: =SUM(F12:F15) -> 45961 | G16: =SUM(G12:G15) -> 280169 | H16: =SUM(H12:H15) -> 56033.8
A18: AVAILABLE INVENTORY BY SIZE × WAREHOUSE
A19: Size | B19: CLT | C19: DAL | D19: SAN | E19: STL | F19: WOO | G19: TOTAL | H19: Avg per WH
A20: Small | B20: =SUMIFS(global_inventory_export11182025!J:J,global_inventory_export11182025!D:D,"Small",global_inventory_export11182025!F:F,"CLT") -> 8450 | C20: =SUMIFS(global_inventory_export11182025!J:J,global_inventory_export11182025!D:D,"Small",global_inventory_export11182025!F:F,"DAL") -> 8568 | D20: =SUMIFS(global_inventory_export11182025!J:J,global_inventory_export11182025!D:D,"Small",global_inventory_export11182025!F:F,"SAN") -> 28 | E20: =SUMIFS(global_inventory_export11182025!J:J,global_inventory_export11182025!D:D,"Small",global_inventory_export11182025!F:F,"STL") -> 13207 | F20: =SUMIFS(global_inventory_export11182025!J:J,global_inventory_export11182025!D:D,"Small",global_inventory_export11182025!F:F,"WOO") -> 8008 | G20: =SUM(B20:F20) -> 38261 | H20: =AVERAGE(B20:F20) -> 7652.2
A21: Medium | B21: =SUMIFS(global_inventory_export11182025!J:J,global_inventory_export11182025!D:D,"Medium",global_inventory_export11182025!F:F,"CLT") -> 12364 | C21: =SUMIFS(global_inventory_export11182025!J:J,global_inventory_export11182025!D:D,"Medium",global_inventory_export11182025!F:F,"DAL") -> 14951 | D21: =SUMIFS(global_inventory_export11182025!J:J,global_inventory_export11182025!D:D,"Medium",global_inventory_export11182025!F:F,"SAN") -> 24 | E21: =SUMIFS(global_inventory_export11182025!J:J,global_inventory_export11182025!D:D,"Medium",global_inventory_export11182025!F:F,"STL") -> 13113 | F21: =SUMIFS(global_inventory_export11182025!J:J,global_inventory_export11182025!D:D,"Medium",global_inventory_export11182025!F:F,"WOO") -> 10995 | G21: =SUM(B21:F21) -> 51447 | H21: =AVERAGE(B21:F21) -> 10289.4
A22: Large | B22: =SUMIFS(global_inventory_export11182025!J:J,global_inventory_export11182025!D:D,"Large",global_inventory_export11182025!F:F,"CLT") -> 8960 | C22: =SUMIFS(global_inventory_export11182025!J:J,global_inventory_export11182025!D:D,"Large",global_inventory_export11182025!F:F,"DAL") -> 9958 | D22: =SUMIFS(global_inventory_export11182025!J:J,global_inventory_export11182025!D:D,"Large",global_inventory_export11182025!F:F,"SAN") -> 24 | E22: =SUMIFS(global_inventory_export11182025!J:J,global_inventory_export11182025!D:D,"Large",global_inventory_export11182025!F:F,"STL") -> 16897 | F22: =SUMIFS(global_inventory_export11182025!J:J,global_inventory_export11182025!D:D,"Large",global_inventory_export11182025!F:F,"WOO") -> 12747 | G22: =SUM(B22:F22) -> 48586 | H22: =AVERAGE(B22:F22) -> 9717.2
A23: Extra Large | B23: =SUMIFS(global_inventory_export11182025!J:J,global_inventory_export11182025!D:D,"Extra Large",global_inventory_export11182025!F:F,"CLT") -> 7386 | C23: =SUMIFS(global_inventory_export11182025!J:J,global_inventory_export11182025!D:D,"Extra Large",global_inventory_export11182025!F:F,"DAL") -> 9418 | D23: =SUMIFS(global_inventory_export11182025!J:J,global_inventory_export11182025!D:D,"Extra Large",global_inventory_export11182025!F:F,"SAN") -> 30 | E23: =SUMIFS(global_inventory_export11182025!J:J,global_inventory_export11182025!D:D,"Extra Large",global_inventory_export11182025!F:F,"STL") -> 10444 | F23: =SUMIFS(global_inventory_export11182025!J:J,global_inventory_export11182025!D:D,"Extra Large",global_inventory_export11182025!F:F,"WOO") -> 12450 | G23: =SUM(B23:F23) -> 39728 | H23: =AVERAGE(B23:F23) -> 7945.6
A24: US 8 | B24: =SUMIFS(global_inventory_export11182025!J:J,global_inventory_export11182025!D:D,"US 8",global_inventory_export11182025!F:F,"CLT") -> 6954 | C24: =SUMIFS(global_inventory_export11182025!J:J,global_inventory_export11182025!D:D,"US 8",global_inventory_export11182025!F:F,"DAL") -> 8376 | D24: =SUMIFS(global_inventory_export11182025!J:J,global_inventory_export11182025!D:D,"US 8",global_inventory_export11182025!F:F,"SAN") -> 5 | E24: =SUMIFS(global_inventory_export11182025!J:J,global_inventory_export11182025!D:D,"US 8",global_inventory_export11182025!F:F,"STL") -> 7055 | F24: =SUMIFS(global_inventory_export11182025!J:J,global_inventory_export11182025!D:D,"US 8",global_inventory_export11182025!F:F,"WOO") -> 302 | G24: =SUM(B24:F24) -> 22692 | H24: =AVERAGE(B24:F24) -> 4538.4
A25: US 9 | B25: =SUMIFS(global_inventory_export11182025!J:J,global_inventory_export11182025!D:D,"US 9",global_inventory_export11182025!F:F,"CLT") -> 7488 | C25: =SUMIFS(global_inventory_export11182025!J:J,global_inventory_export11182025!D:D,"US 9",global_inventory_export11182025!F:F,"DAL") -> 8202 | D25: =SUMIFS(global_inventory_export11182025!J:J,global_inventory_export11182025!D:D,"US 9",global_inventory_export11182025!F:F,"SAN") -> 7 | E25: =SUMIFS(global_inventory_export11182025!J:J,global_inventory_export11182025!D:D,"US 9",global_inventory_export11182025!F:F,"STL") -> 7579 | F25: =SUMIFS(global_inventory_export11182025!J:J,global_inventory_export11182025!D:D,"US 9",global_inventory_export11182025!F:F,"WOO") -> 447 | G25: =SUM(B25:F25) -> 23723 | H25: =AVERAGE(B25:F25) -> 4744.6
A26: US 10 | B26: =SUMIFS(global_inventory_export11182025!J:J,global_inventory_export11182025!D:D,"US 10",global_inventory_export11182025!F:F,"CLT") -> 9974 | C26: =SUMIFS(global_inventory_export11182025!J:J,global_inventory_export11182025!D:D,"US 10",global_inventory_export11182025!F:F,"DAL") -> 8486 | D26: =SUMIFS(global_inventory_export11182025!J:J,global_inventory_export11182025!D:D,"US 10",global_inventory_export11182025!F:F,"SAN") -> 6 | E26: =SUMIFS(global_inventory_export11182025!J:J,global_inventory_export11182025!D:D,"US 10",global_inventory_export11182025!F:F,"STL") -> 8316 | F26: =SUMIFS(global_inventory_export11182025!J:J,global_inventory_export11182025!D:D,"US 10",global_inventory_export11182025!F:F,"WOO") -> 564 | G26: =SUM(B26:F26) -> 27346 | H26: =AVERAGE(B26:F26) -> 5469.2
A27: US 11 | B27: =SUMIFS(global_inventory_export11182025!J:J,global_inventory_export11182025!D:D,"US 11",global_inventory_export11182025!F:F,"CLT") -> 8909 | C27: =SUMIFS(global_inventory_export11182025!J:J,global_inventory_export11182025!D:D,"US 11",global_inventory_export11182025!F:F,"DAL") -> 9151 | D27: =SUMIFS(global_inventory_export11182025!J:J,global_inventory_export11182025!D:D,"US 11",global_inventory_export11182025!F:F,"SAN") -> 5 | E27: =SUMIFS(global_inventory_export11182025!J:J,global_inventory_export11182025!D:D,"US 11",global_inventory_export11182025!F:F,"STL") -> 9873 | F27: =SUMIFS(global_inventory_export11182025!J:J,global_inventory_export11182025!D:D,"US 11",global_inventory_export11182025!F:F,"WOO") -> 448 | G27: =SUM(B27:F27) -> 28386 | H27: =AVERAGE(B27:F27) -> 5677.2
A28: TOTAL | B28: =SUM(B20:B27) -> 70485 | C28: =SUM(C20:C27) -> 77110 | D28: =SUM(D20:D27) -> 129 | E28: =SUM(E20:E27) -> 86484 | F28: =SUM(F20:F27) -> 45961 | G28: =SUM(G20:G27) -> 280169 | H28: =SUM(H20:H27) -> 56033.8
A30: AT-RISK ITEMS: Available Qty Below Reorder Point (sorted by deficit)
A31: SKU ID | B31: Product | C31: Size | D31: Color | E31: Warehouse | F31: Qty On Hand | G31: Qty Allocated | H31: Qty Available | I31: Reorder Point | J31: Deficit | K31: Risk Level | L31: Status
A32: ZCSAJ-SS-XL-O | B32: ZavaCore Systems Athletic Jersey | C32: Extra Large | D32: Orange | E32: SAN | F32: 7 | G32: 2 | H32: 5 | I32: 695 | J32: 690 | K32: =IF(H32=0,"CRITICAL",IF(J32>200,"HIGH","MEDIUM")) -> HIGH | L32: Active
A33: ZCFET-SS-M-BO | B33: ZavaCore Field Elite Tee | C33: Medium | D33: Black/Orange | E33: SAN | F33: 3 | G33: 2 | H33: 1 | I33: 687 | J33: 686 | K33: =IF(H33=0,"CRITICAL",IF(J33>200,"HIGH","MEDIUM")) -> HIGH | L33: Active
A34: ZCSAJ-SS-M-O | B34: ZavaCore Systems Athletic Jersey | C34: Medium | D34: Orange | E34: SAN | F34: 6 | G34: 2 | H34: 4 | I34: 679 | J34: 675 | K34: =IF(H34=0,"CRITICAL",IF(J34>200,"HIGH","MEDIUM")) -> HIGH | L34: Active
A35: ZCFET-SS-S-BO | B35: ZavaCore Field Elite Tee | C35: Small | D35: Black/Orange | E35: SAN | F35: 6 | G35: 1 | H35: 5 | I35: 679 | J35: 674 | K35: =IF(H35=0,"CRITICAL",IF(J35>200,"HIGH","MEDIUM")) -> HIGH | L35: Active
A36: ZCFPT-SS-L-O | B36: ZavaCore Field Premium Tee | C36: Large | D36: Orange | E36: SAN | F36: 4 | G36: 2 | H36: 2 | I36: 668 | J36: 666 | K36: =IF(H36=0,"CRITICAL",IF(J36>200,"HIGH","MEDIUM")) -> HIGH | L36: Active
A37: ZCSC-SS-9-O | B37: ZavaCore Smart Cleats | C37: US 9 | D37: Orange | E37: SAN | F37: 4 | G37: 2 | H37: 2 | I37: 628 | J37: 626 | K37: =IF(H37=0,"CRITICAL",IF(J37>200,"HIGH","MEDIUM")) -> HIGH | L37: Active
A38: ZCFET-SS-L-B | B38: ZavaCore Field Elite Tee | C38: Large | D38: Black | E38: SAN | F38: 6 | G38: 1 | H38: 5 | I38: 621 | J38: 616 | K38: =IF(H38=0,"CRITICAL",IF(J38>200,"HIGH","MEDIUM")) -> HIGH | L38: Active
A39: ZCFET-SS-L-BO | B39: ZavaCore Field Elite Tee | C39: Large | D39: Black/Orange | E39: SAN | F39: 6 | G39: 1 | H39: 5 | I39: 566 | J39: 561 | K39: =IF(H39=0,"CRITICAL",IF(J39>200,"HIGH","MEDIUM")) -> HIGH | L39: Active
A40: ZCFPT-SS-S-BO | B40: ZavaCore Field Premium Tee | C40: Small | D40: Black/Orange | E40: SAN | F40: 7 | G40: 2 | H40: 5 | I40: 564 | J40: 559 | K40: =IF(H40=0,"CRITICAL",IF(J40>200,"HIGH","MEDIUM")) -> HIGH | L40: Active
A41: ZCSAJ-SS-S-B | B41: ZavaCore Systems Athletic Jersey | C41: Small | D41: Black | E41: SAN | F41: 7 | G41: 2 | H41: 5 | I41: 563 | J41: 558 | K41: =IF(H41=0,"CRITICAL",IF(J41>200,"HIGH","MEDIUM")) -> HIGH | L41: Active
A42: ZCFPT-SS-XL-O | B42: ZavaCore Field Premium Tee | C42: Extra Large | D42: Orange | E42: SAN | F42: 2 | G42: 0 | H42: 2 | I42: 543 | J42: 541 | K42: =IF(H42=0,"CRITICAL",IF(J42>200,"HIGH","MEDIUM")) -> HIGH | L42: Active
A43: ZCFPT-SS-S-B | B43: ZavaCore Field Premium Tee | C43: Small | D43: Black | E43: SAN | F43: 3 | G43: 2 | H43: 1 | I43: 534 | J43: 533 | K43: =IF(H43=0,"CRITICAL",IF(J43>200,"HIGH","MEDIUM")) -> HIGH | L43: Active
...
